<?xml version="1.0" ?>
<!-- =================================================================================== -->
<!-- |    This document was autogenerated by xacro from main.xacro                     | -->
<!-- |    EDITING THIS FILE BY HAND IS NOT RECOMMENDED                                 | -->
<!-- =================================================================================== -->
<robot name="omni_bot" xmlns:xacro="http://ros.org/wiki/xacro">
  <link name="base_link">
    <inertial>
      <origin rpy="1.57 0 0" xyz="0 0 0"/>
      <mass value="0.10"/>
      <inertia ixx="0.00092" ixy="0.0" ixz="0.0" iyy="0.00178" iyz="0.0" izz="0.00092"/>
    </inertial>
    <visual>
      <origin rpy="1.57 0 0" xyz="0 0 0"/>
      <geometry>
        <mesh filename="omni_base.STL"/>
      </geometry>
      <material name="darkgray">
        <color rgba=".1 .5 .2 1"/>
      </material>
    </visual>
    <collision>
      <origin rpy="1.57 0 0" xyz="0 0 0"/>
      <geometry>
        <mesh filename="omni_base.STL"/>
      </geometry>
    </collision>
  </link>
  <link name="rim_left_link">
    <inertial>
      <mass value="0.10"/>
      <inertia ixx="7.6e-5" ixy="0.0" ixz="0.0" iyy="7.6e-5" iyz="0.0" izz="0.000125"/>
    </inertial>
    <visual>
      <geometry>
        <cylinder length="0.04" radius="0.05"/>
      </geometry>
    </visual>
    <collision>
      <geometry>
        <cylinder length="0.04" radius="0.05"/>
      </geometry>
    </collision>
  </link>
  <joint name="base_link_rim_left_joint" type="continuous">
    <parent link="base_link"/>
    <child link="rim_left_link"/>
    <axis xyz="0 0 1"/>
    <origin rpy="1.57 1.57 0.5233" xyz="-0.1256 0.213875 0.025"/>
    <limit effort="1000" velocity="3140"/>
  </joint>
  <link name="roller_6_rim_left_link">
    <inertial>
      <inertia ixx="1e-6" ixy="0.0" ixz="0.0" iyy="1e-6" iyz="0.0" izz="1e-7"/>
      <mass value="0.010"/>
    </inertial>
    <visual>
      <geometry>
        <cylinder length="0.03" radius="0.01"/>
      </geometry>
    </visual>
    <collision>
      <geometry>
        <cylinder length="0.03" radius="0.01"/>
      </geometry>
    </collision>
  </link>
  <joint name="roller_6_rim_left_joint" type="continuous">
    <parent link="rim_left_link"/>
    <child link="roller_6_rim_left_link"/>
    <axis xyz="0 0 1"/>
    <origin rpy="1.57 0 0" xyz="0.06 0 0.01"/>
    <limit effort="1000" velocity="31.4"/>
  </joint>
  <link name="roller_5_rim_left_link">
    <inertial>
      <inertia ixx="1e-6" ixy="0.0" ixz="0.0" iyy="1e-6" iyz="0.0" izz="1e-7"/>
      <mass value="0.010"/>
    </inertial>
    <visual>
      <geometry>
        <cylinder length="0.03" radius="0.01"/>
      </geometry>
    </visual>
    <collision>
      <geometry>
        <cylinder length="0.03" radius="0.01"/>
      </geometry>
    </collision>
  </link>
  <joint name="roller_5_rim_left_joint" type="continuous">
    <parent link="rim_left_link"/>
    <child link="roller_5_rim_left_link"/>
    <axis xyz="0 0 1"/>
    <origin rpy="1.57 0 0.5233" xyz="0.05196 0.03 -0.01"/>
    <limit effort="1000" velocity="31.4"/>
  </joint>
  <link name="roller_4_rim_left_link">
    <inertial>
      <inertia ixx="1e-6" ixy="0.0" ixz="0.0" iyy="1e-6" iyz="0.0" izz="1e-7"/>
      <mass value="0.010"/>
    </inertial>
    <visual>
      <geometry>
        <cylinder length="0.03" radius="0.01"/>
      </geometry>
    </visual>
    <collision>
      <geometry>
        <cylinder length="0.03" radius="0.01"/>
      </geometry>
    </collision>
  </link>
  <joint name="roller_4_rim_left_joint" type="continuous">
    <parent link="rim_left_link"/>
    <child link="roller_4_rim_left_link"/>
    <axis xyz="0 0 1"/>
    <origin rpy="1.57 0 1.0466" xyz="0.03 0.05196 0.01"/>
    <limit effort="1000" velocity="31.4"/>
  </joint>
  <link name="roller_3_rim_left_link">
    <inertial>
      <inertia ixx="1e-6" ixy="0.0" ixz="0.0" iyy="1e-6" iyz="0.0" izz="1e-7"/>
      <mass value="0.010"/>
    </inertial>
    <visual>
      <geometry>
        <cylinder length="0.03" radius="0.01"/>
      </geometry>
    </visual>
    <collision>
      <geometry>
        <cylinder length="0.03" radius="0.01"/>
      </geometry>
    </collision>
  </link>
  <joint name="roller_3_rim_left_joint" type="continuous">
    <parent link="rim_left_link"/>
    <child link="roller_3_rim_left_link"/>
    <axis xyz="0 0 1"/>
    <origin rpy="1.57 0 1.5699" xyz="0.0 0.06 -0.01"/>
    <limit effort="1000" velocity="31.4"/>
  </joint>
  <link name="roller_2_rim_left_link">
    <inertial>
      <inertia ixx="1e-6" ixy="0.0" ixz="0.0" iyy="1e-6" iyz="0.0" izz="1e-7"/>
      <mass value="0.010"/>
    </inertial>
    <visual>
      <geometry>
        <cylinder length="0.03" radius="0.01"/>
      </geometry>
    </visual>
    <collision>
      <geometry>
        <cylinder length="0.03" radius="0.01"/>
      </geometry>
    </collision>
  </link>
  <joint name="roller_2_rim_left_joint" type="continuous">
    <parent link="rim_left_link"/>
    <child link="roller_2_rim_left_link"/>
    <axis xyz="0 0 1"/>
    <origin rpy="1.57 0 2.0932" xyz="-0.03 0.05196 0.01"/>
    <limit effort="1000" velocity="31.4"/>
  </joint>
  <link name="roller_1_rim_left_link">
    <inertial>
      <inertia ixx="1e-6" ixy="0.0" ixz="0.0" iyy="1e-6" iyz="0.0" izz="1e-7"/>
      <mass value="0.010"/>
    </inertial>
    <visual>
      <geometry>
        <cylinder length="0.03" radius="0.01"/>
      </geometry>
    </visual>
    <collision>
      <geometry>
        <cylinder length="0.03" radius="0.01"/>
      </geometry>
    </collision>
  </link>
  <joint name="roller_1_rim_left_joint" type="continuous">
    <parent link="rim_left_link"/>
    <child link="roller_1_rim_left_link"/>
    <axis xyz="0 0 1"/>
    <origin rpy="1.57 0 2.6165" xyz="-0.05196 0.03 -0.01"/>
    <limit effort="1000" velocity="31.4"/>
  </joint>
  <link name="roller_12_rim_left_link">
    <inertial>
      <inertia ixx="1e-6" ixy="0.0" ixz="0.0" iyy="1e-6" iyz="0.0" izz="1e-7"/>
      <mass value="0.010"/>
    </inertial>
    <visual>
      <geometry>
        <cylinder length="0.03" radius="0.01"/>
      </geometry>
    </visual>
    <collision>
      <geometry>
        <cylinder length="0.03" radius="0.01"/>
      </geometry>
    </collision>
  </link>
  <joint name="roller_12_rim_left_joint" type="continuous">
    <parent link="rim_left_link"/>
    <child link="roller_12_rim_left_link"/>
    <axis xyz="0 0 1"/>
    <origin rpy="1.57 0 3.1398" xyz="-0.06 0.00 0.01"/>
    <limit effort="1000" velocity="31.4"/>
  </joint>
  <link name="roller_11_rim_left_link">
    <inertial>
      <inertia ixx="1e-6" ixy="0.0" ixz="0.0" iyy="1e-6" iyz="0.0" izz="1e-7"/>
      <mass value="0.010"/>
    </inertial>
    <visual>
      <geometry>
        <cylinder length="0.03" radius="0.01"/>
      </geometry>
    </visual>
    <collision>
      <geometry>
        <cylinder length="0.03" radius="0.01"/>
      </geometry>
    </collision>
  </link>
  <joint name="roller_11_rim_left_joint" type="continuous">
    <parent link="rim_left_link"/>
    <child link="roller_11_rim_left_link"/>
    <axis xyz="0 0 1"/>
    <origin rpy="1.57 0 -2.6165" xyz="-0.05196 -0.03 -0.01"/>
    <limit effort="1000" velocity="31.4"/>
  </joint>
  <link name="roller_10_rim_left_link">
    <inertial>
      <inertia ixx="1e-6" ixy="0.0" ixz="0.0" iyy="1e-6" iyz="0.0" izz="1e-7"/>
      <mass value="0.010"/>
    </inertial>
    <visual>
      <geometry>
        <cylinder length="0.03" radius="0.01"/>
      </geometry>
    </visual>
    <collision>
      <geometry>
        <cylinder length="0.03" radius="0.01"/>
      </geometry>
    </collision>
  </link>
  <joint name="roller_10_rim_left_joint" type="continuous">
    <parent link="rim_left_link"/>
    <child link="roller_10_rim_left_link"/>
    <axis xyz="0 0 1"/>
    <origin rpy="1.57 0 -2.0932" xyz="-0.03 -0.05196 0.01"/>
    <limit effort="1000" velocity="31.4"/>
  </joint>
  <link name="roller_9_rim_left_link">
    <inertial>
      <inertia ixx="1e-6" ixy="0.0" ixz="0.0" iyy="1e-6" iyz="0.0" izz="1e-7"/>
      <mass value="0.010"/>
    </inertial>
    <visual>
      <geometry>
        <cylinder length="0.03" radius="0.01"/>
      </geometry>
    </visual>
    <collision>
      <geometry>
        <cylinder length="0.03" radius="0.01"/>
      </geometry>
    </collision>
  </link>
  <joint name="roller_9_rim_left_joint" type="continuous">
    <parent link="rim_left_link"/>
    <child link="roller_9_rim_left_link"/>
    <axis xyz="0 0 1"/>
    <origin rpy="1.57 0 -1.5699" xyz="0.0 -0.06 -0.01"/>
    <limit effort="1000" velocity="31.4"/>
  </joint>
  <link name="roller_8_rim_left_link">
    <inertial>
      <inertia ixx="1e-6" ixy="0.0" ixz="0.0" iyy="1e-6" iyz="0.0" izz="1e-7"/>
      <mass value="0.010"/>
    </inertial>
    <visual>
      <geometry>
        <cylinder length="0.03" radius="0.01"/>
      </geometry>
    </visual>
    <collision>
      <geometry>
        <cylinder length="0.03" radius="0.01"/>
      </geometry>
    </collision>
  </link>
  <joint name="roller_8_rim_left_joint" type="continuous">
    <parent link="rim_left_link"/>
    <child link="roller_8_rim_left_link"/>
    <axis xyz="0 0 1"/>
    <origin rpy="1.57 0 -1.0466" xyz="0.03 -0.05196 0.01"/>
    <limit effort="1000" velocity="31.4"/>
  </joint>
  <link name="roller_7_rim_left_link">
    <inertial>
      <inertia ixx="1e-6" ixy="0.0" ixz="0.0" iyy="1e-6" iyz="0.0" izz="1e-7"/>
      <mass value="0.010"/>
    </inertial>
    <visual>
      <geometry>
        <cylinder length="0.03" radius="0.01"/>
      </geometry>
    </visual>
    <collision>
      <geometry>
        <cylinder length="0.03" radius="0.01"/>
      </geometry>
    </collision>
  </link>
  <joint name="roller_7_rim_left_joint" type="continuous">
    <parent link="rim_left_link"/>
    <child link="roller_7_rim_left_link"/>
    <axis xyz="0 0 1"/>
    <origin rpy="1.57 0 -0.5233" xyz="0.05196 -0.03 -0.01"/>
    <limit effort="1000" velocity="31.4"/>
  </joint>
  <transmission name="left_wheel_tran">
    <type>transmission_interface/SimpleTransmission</type>
    <joint name="base_link_rim_left_joint">
      <hardwareInterface>hardware_interface/EffortJointInterface</hardwareInterface>
    </joint>
    <actuator name="left_wheel_motor">
      <hardwareInterface>hardware_interface/EffortJointInterface</hardwareInterface>
      <mechanicalReduction>1</mechanicalReduction>
    </actuator>
  </transmission>
  <gazebo reference="rim_left_link">
    <material value="Gazebo/Red"/>
  </gazebo>
  <link name="rim_right_link">
    <inertial>
      <mass value="0.10"/>
      <inertia ixx="7.6e-5" ixy="0.0" ixz="0.0" iyy="7.6e-5" iyz="0.0" izz="0.000125"/>
    </inertial>
    <visual>
      <geometry>
        <cylinder length="0.04" radius="0.05"/>
      </geometry>
    </visual>
    <collision>
      <geometry>
        <cylinder length="0.04" radius="0.05"/>
      </geometry>
    </collision>
  </link>
  <joint name="base_link_rim_right_joint" type="continuous">
    <parent link="base_link"/>
    <child link="rim_right_link"/>
    <axis xyz="0 0 1"/>
    <origin rpy="1.57 1.57 2.6167" xyz="-0.1256 -0.213875 0.025"/>
    <limit effort="1000" velocity="3140"/>
  </joint>
  <link name="roller_6_rim_right_link">
    <inertial>
      <inertia ixx="1e-6" ixy="0.0" ixz="0.0" iyy="1e-6" iyz="0.0" izz="1e-7"/>
      <mass value="0.010"/>
    </inertial>
    <visual>
      <geometry>
        <cylinder length="0.03" radius="0.01"/>
      </geometry>
    </visual>
    <collision>
      <geometry>
        <cylinder length="0.03" radius="0.01"/>
      </geometry>
    </collision>
  </link>
  <joint name="roller_6_rim_right_joint" type="continuous">
    <parent link="rim_right_link"/>
    <child link="roller_6_rim_right_link"/>
    <axis xyz="0 0 1"/>
    <origin rpy="1.57 0 0" xyz="0.06 0 0.01"/>
    <limit effort="1000" velocity="31.4"/>
  </joint>
  <link name="roller_5_rim_right_link">
    <inertial>
      <inertia ixx="1e-6" ixy="0.0" ixz="0.0" iyy="1e-6" iyz="0.0" izz="1e-7"/>
      <mass value="0.010"/>
    </inertial>
    <visual>
      <geometry>
        <cylinder length="0.03" radius="0.01"/>
      </geometry>
    </visual>
    <collision>
      <geometry>
        <cylinder length="0.03" radius="0.01"/>
      </geometry>
    </collision>
  </link>
  <joint name="roller_5_rim_right_joint" type="continuous">
    <parent link="rim_right_link"/>
    <child link="roller_5_rim_right_link"/>
    <axis xyz="0 0 1"/>
    <origin rpy="1.57 0 0.5233" xyz="0.05196 0.03 -0.01"/>
    <limit effort="1000" velocity="31.4"/>
  </joint>
  <link name="roller_4_rim_right_link">
    <inertial>
      <inertia ixx="1e-6" ixy="0.0" ixz="0.0" iyy="1e-6" iyz="0.0" izz="1e-7"/>
      <mass value="0.010"/>
    </inertial>
    <visual>
      <geometry>
        <cylinder length="0.03" radius="0.01"/>
      </geometry>
    </visual>
    <collision>
      <geometry>
        <cylinder length="0.03" radius="0.01"/>
      </geometry>
    </collision>
  </link>
  <joint name="roller_4_rim_right_joint" type="continuous">
    <parent link="rim_right_link"/>
    <child link="roller_4_rim_right_link"/>
    <axis xyz="0 0 1"/>
    <origin rpy="1.57 0 1.0466" xyz="0.03 0.05196 0.01"/>
    <limit effort="1000" velocity="31.4"/>
  </joint>
  <link name="roller_3_rim_right_link">
    <inertial>
      <inertia ixx="1e-6" ixy="0.0" ixz="0.0" iyy="1e-6" iyz="0.0" izz="1e-7"/>
      <mass value="0.010"/>
    </inertial>
    <visual>
      <geometry>
        <cylinder length="0.03" radius="0.01"/>
      </geometry>
    </visual>
    <collision>
      <geometry>
        <cylinder length="0.03" radius="0.01"/>
      </geometry>
    </collision>
  </link>
  <joint name="roller_3_rim_right_joint" type="continuous">
    <parent link="rim_right_link"/>
    <child link="roller_3_rim_right_link"/>
    <axis xyz="0 0 1"/>
    <origin rpy="1.57 0 1.5699" xyz="0.0 0.06 -0.01"/>
    <limit effort="1000" velocity="31.4"/>
  </joint>
  <link name="roller_2_rim_right_link">
    <inertial>
      <inertia ixx="1e-6" ixy="0.0" ixz="0.0" iyy="1e-6" iyz="0.0" izz="1e-7"/>
      <mass value="0.010"/>
    </inertial>
    <visual>
      <geometry>
        <cylinder length="0.03" radius="0.01"/>
      </geometry>
    </visual>
    <collision>
      <geometry>
        <cylinder length="0.03" radius="0.01"/>
      </geometry>
    </collision>
  </link>
  <joint name="roller_2_rim_right_joint" type="continuous">
    <parent link="rim_right_link"/>
    <child link="roller_2_rim_right_link"/>
    <axis xyz="0 0 1"/>
    <origin rpy="1.57 0 2.0932" xyz="-0.03 0.05196 0.01"/>
    <limit effort="1000" velocity="31.4"/>
  </joint>
  <link name="roller_1_rim_right_link">
    <inertial>
      <inertia ixx="1e-6" ixy="0.0" ixz="0.0" iyy="1e-6" iyz="0.0" izz="1e-7"/>
      <mass value="0.010"/>
    </inertial>
    <visual>
      <geometry>
        <cylinder length="0.03" radius="0.01"/>
      </geometry>
    </visual>
    <collision>
      <geometry>
        <cylinder length="0.03" radius="0.01"/>
      </geometry>
    </collision>
  </link>
  <joint name="roller_1_rim_right_joint" type="continuous">
    <parent link="rim_right_link"/>
    <child link="roller_1_rim_right_link"/>
    <axis xyz="0 0 1"/>
    <origin rpy="1.57 0 2.6165" xyz="-0.05196 0.03 -0.01"/>
    <limit effort="1000" velocity="31.4"/>
  </joint>
  <link name="roller_12_rim_right_link">
    <inertial>
      <inertia ixx="1e-6" ixy="0.0" ixz="0.0" iyy="1e-6" iyz="0.0" izz="1e-7"/>
      <mass value="0.010"/>
    </inertial>
    <visual>
      <geometry>
        <cylinder length="0.03" radius="0.01"/>
      </geometry>
    </visual>
    <collision>
      <geometry>
        <cylinder length="0.03" radius="0.01"/>
      </geometry>
    </collision>
  </link>
  <joint name="roller_12_rim_right_joint" type="continuous">
    <parent link="rim_right_link"/>
    <child link="roller_12_rim_right_link"/>
    <axis xyz="0 0 1"/>
    <origin rpy="1.57 0 3.1398" xyz="-0.06 0.00 0.01"/>
    <limit effort="1000" velocity="31.4"/>
  </joint>
  <link name="roller_11_rim_right_link">
    <inertial>
      <inertia ixx="1e-6" ixy="0.0" ixz="0.0" iyy="1e-6" iyz="0.0" izz="1e-7"/>
      <mass value="0.010"/>
    </inertial>
    <visual>
      <geometry>
        <cylinder length="0.03" radius="0.01"/>
      </geometry>
    </visual>
    <collision>
      <geometry>
        <cylinder length="0.03" radius="0.01"/>
      </geometry>
    </collision>
  </link>
  <joint name="roller_11_rim_right_joint" type="continuous">
    <parent link="rim_right_link"/>
    <child link="roller_11_rim_right_link"/>
    <axis xyz="0 0 1"/>
    <origin rpy="1.57 0 -2.6165" xyz="-0.05196 -0.03 -0.01"/>
    <limit effort="1000" velocity="31.4"/>
  </joint>
  <link name="roller_10_rim_right_link">
    <inertial>
      <inertia ixx="1e-6" ixy="0.0" ixz="0.0" iyy="1e-6" iyz="0.0" izz="1e-7"/>
      <mass value="0.010"/>
    </inertial>
    <visual>
      <geometry>
        <cylinder length="0.03" radius="0.01"/>
      </geometry>
    </visual>
    <collision>
      <geometry>
        <cylinder length="0.03" radius="0.01"/>
      </geometry>
    </collision>
  </link>
  <joint name="roller_10_rim_right_joint" type="continuous">
    <parent link="rim_right_link"/>
    <child link="roller_10_rim_right_link"/>
    <axis xyz="0 0 1"/>
    <origin rpy="1.57 0 -2.0932" xyz="-0.03 -0.05196 0.01"/>
    <limit effort="1000" velocity="31.4"/>
  </joint>
  <link name="roller_9_rim_right_link">
    <inertial>
      <inertia ixx="1e-6" ixy="0.0" ixz="0.0" iyy="1e-6" iyz="0.0" izz="1e-7"/>
      <mass value="0.010"/>
    </inertial>
    <visual>
      <geometry>
        <cylinder length="0.03" radius="0.01"/>
      </geometry>
    </visual>
    <collision>
      <geometry>
        <cylinder length="0.03" radius="0.01"/>
      </geometry>
    </collision>
  </link>
  <joint name="roller_9_rim_right_joint" type="continuous">
    <parent link="rim_right_link"/>
    <child link="roller_9_rim_right_link"/>
    <axis xyz="0 0 1"/>
    <origin rpy="1.57 0 -1.5699" xyz="0.0 -0.06 -0.01"/>
    <limit effort="1000" velocity="31.4"/>
  </joint>
  <link name="roller_8_rim_right_link">
    <inertial>
      <inertia ixx="1e-6" ixy="0.0" ixz="0.0" iyy="1e-6" iyz="0.0" izz="1e-7"/>
      <mass value="0.010"/>
    </inertial>
    <visual>
      <geometry>
        <cylinder length="0.03" radius="0.01"/>
      </geometry>
    </visual>
    <collision>
      <geometry>
        <cylinder length="0.03" radius="0.01"/>
      </geometry>
    </collision>
  </link>
  <joint name="roller_8_rim_right_joint" type="continuous">
    <parent link="rim_right_link"/>
    <child link="roller_8_rim_right_link"/>
    <axis xyz="0 0 1"/>
    <origin rpy="1.57 0 -1.0466" xyz="0.03 -0.05196 0.01"/>
    <limit effort="1000" velocity="31.4"/>
  </joint>
  <link name="roller_7_rim_right_link">
    <inertial>
      <inertia ixx="1e-6" ixy="0.0" ixz="0.0" iyy="1e-6" iyz="0.0" izz="1e-7"/>
      <mass value="0.010"/>
    </inertial>
    <visual>
      <geometry>
        <cylinder length="0.03" radius="0.01"/>
      </geometry>
    </visual>
    <collision>
      <geometry>
        <cylinder length="0.03" radius="0.01"/>
      </geometry>
    </collision>
  </link>
  <joint name="roller_7_rim_right_joint" type="continuous">
    <parent link="rim_right_link"/>
    <child link="roller_7_rim_right_link"/>
    <axis xyz="0 0 1"/>
    <origin rpy="1.57 0 -0.5233" xyz="0.05196 -0.03 -0.01"/>
    <limit effort="1000" velocity="31.4"/>
  </joint>
  <transmission name="right_wheel_tran">
    <type>transmission_interface/SimpleTransmission</type>
    <joint name="base_link_rim_right_joint">
      <hardwareInterface>hardware_interface/EffortJointInterface</hardwareInterface>
    </joint>
    <actuator name="right_wheel_motor">
      <hardwareInterface>hardware_interface/EffortJointInterface</hardwareInterface>
      <mechanicalReduction>1</mechanicalReduction>
    </actuator>
  </transmission>
  <gazebo reference="rim_right_link">
    <material value="Gazebo/Blue"/>
  </gazebo>
  <link name="rim_front_link">
    <inertial>
      <mass value="0.10"/>
      <inertia ixx="7.6e-5" ixy="0.0" ixz="0.0" iyy="7.6e-5" iyz="0.0" izz="0.000125"/>
    </inertial>
    <visual>
      <geometry>
        <cylinder length="0.04" radius="0.05"/>
      </geometry>
    </visual>
    <collision>
      <geometry>
        <cylinder length="0.04" radius="0.05"/>
      </geometry>
    </collision>
  </link>
  <joint name="base_link_rim_front_joint" type="continuous">
    <parent link="base_link"/>
    <child link="rim_front_link"/>
    <axis xyz="0 0 1"/>
    <origin rpy="1.57 1.57 1.57" xyz="0.251 0 0.025"/>
    <limit effort="1000" velocity="3140"/>
  </joint>
  <link name="roller_6_rim_front_link">
    <inertial>
      <inertia ixx="1e-6" ixy="0.0" ixz="0.0" iyy="1e-6" iyz="0.0" izz="1e-7"/>
      <mass value="0.010"/>
    </inertial>
    <visual>
      <geometry>
        <cylinder length="0.03" radius="0.01"/>
      </geometry>
    </visual>
    <collision>
      <geometry>
        <cylinder length="0.03" radius="0.01"/>
      </geometry>
    </collision>
  </link>
  <joint name="roller_6_rim_front_joint" type="continuous">
    <parent link="rim_front_link"/>
    <child link="roller_6_rim_front_link"/>
    <axis xyz="0 0 1"/>
    <origin rpy="1.57 0 0" xyz="0.06 0 0.01"/>
    <limit effort="1000" velocity="31.4"/>
  </joint>
  <link name="roller_5_rim_front_link">
    <inertial>
      <inertia ixx="1e-6" ixy="0.0" ixz="0.0" iyy="1e-6" iyz="0.0" izz="1e-7"/>
      <mass value="0.010"/>
    </inertial>
    <visual>
      <geometry>
        <cylinder length="0.03" radius="0.01"/>
      </geometry>
    </visual>
    <collision>
      <geometry>
        <cylinder length="0.03" radius="0.01"/>
      </geometry>
    </collision>
  </link>
  <joint name="roller_5_rim_front_joint" type="continuous">
    <parent link="rim_front_link"/>
    <child link="roller_5_rim_front_link"/>
    <axis xyz="0 0 1"/>
    <origin rpy="1.57 0 0.5233" xyz="0.05196 0.03 -0.01"/>
    <limit effort="1000" velocity="31.4"/>
  </joint>
  <link name="roller_4_rim_front_link">
    <inertial>
      <inertia ixx="1e-6" ixy="0.0" ixz="0.0" iyy="1e-6" iyz="0.0" izz="1e-7"/>
      <mass value="0.010"/>
    </inertial>
    <visual>
      <geometry>
        <cylinder length="0.03" radius="0.01"/>
      </geometry>
    </visual>
    <collision>
      <geometry>
        <cylinder length="0.03" radius="0.01"/>
      </geometry>
    </collision>
  </link>
  <joint name="roller_4_rim_front_joint" type="continuous">
    <parent link="rim_front_link"/>
    <child link="roller_4_rim_front_link"/>
    <axis xyz="0 0 1"/>
    <origin rpy="1.57 0 1.0466" xyz="0.03 0.05196 0.01"/>
    <limit effort="1000" velocity="31.4"/>
  </joint>
  <link name="roller_3_rim_front_link">
    <inertial>
      <inertia ixx="1e-6" ixy="0.0" ixz="0.0" iyy="1e-6" iyz="0.0" izz="1e-7"/>
      <mass value="0.010"/>
    </inertial>
    <visual>
      <geometry>
        <cylinder length="0.03" radius="0.01"/>
      </geometry>
    </visual>
    <collision>
      <geometry>
        <cylinder length="0.03" radius="0.01"/>
      </geometry>
    </collision>
  </link>
  <joint name="roller_3_rim_front_joint" type="continuous">
    <parent link="rim_front_link"/>
    <child link="roller_3_rim_front_link"/>
    <axis xyz="0 0 1"/>
    <origin rpy="1.57 0 1.5699" xyz="0.0 0.06 -0.01"/>
    <limit effort="1000" velocity="31.4"/>
  </joint>
  <link name="roller_2_rim_front_link">
    <inertial>
      <inertia ixx="1e-6" ixy="0.0" ixz="0.0" iyy="1e-6" iyz="0.0" izz="1e-7"/>
      <mass value="0.010"/>
    </inertial>
    <visual>
      <geometry>
        <cylinder length="0.03" radius="0.01"/>
      </geometry>
    </visual>
    <collision>
      <geometry>
        <cylinder length="0.03" radius="0.01"/>
      </geometry>
    </collision>
  </link>
  <joint name="roller_2_rim_front_joint" type="continuous">
    <parent link="rim_front_link"/>
    <child link="roller_2_rim_front_link"/>
    <axis xyz="0 0 1"/>
    <origin rpy="1.57 0 2.0932" xyz="-0.03 0.05196 0.01"/>
    <limit effort="1000" velocity="31.4"/>
  </joint>
  <link name="roller_1_rim_front_link">
    <inertial>
      <inertia ixx="1e-6" ixy="0.0" ixz="0.0" iyy="1e-6" iyz="0.0" izz="1e-7"/>
      <mass value="0.010"/>
    </inertial>
    <visual>
      <geometry>
        <cylinder length="0.03" radius="0.01"/>
      </geometry>
    </visual>
    <collision>
      <geometry>
        <cylinder length="0.03" radius="0.01"/>
      </geometry>
    </collision>
  </link>
  <joint name="roller_1_rim_front_joint" type="continuous">
    <parent link="rim_front_link"/>
    <child link="roller_1_rim_front_link"/>
    <axis xyz="0 0 1"/>
    <origin rpy="1.57 0 2.6165" xyz="-0.05196 0.03 -0.01"/>
    <limit effort="1000" velocity="31.4"/>
  </joint>
  <link name="roller_12_rim_front_link">
    <inertial>
      <inertia ixx="1e-6" ixy="0.0" ixz="0.0" iyy="1e-6" iyz="0.0" izz="1e-7"/>
      <mass value="0.010"/>
    </inertial>
    <visual>
      <geometry>
        <cylinder length="0.03" radius="0.01"/>
      </geometry>
    </visual>
    <collision>
      <geometry>
        <cylinder length="0.03" radius="0.01"/>
      </geometry>
    </collision>
  </link>
  <joint name="roller_12_rim_front_joint" type="continuous">
    <parent link="rim_front_link"/>
    <child link="roller_12_rim_front_link"/>
    <axis xyz="0 0 1"/>
    <origin rpy="1.57 0 3.1398" xyz="-0.06 0.00 0.01"/>
    <limit effort="1000" velocity="31.4"/>
  </joint>
  <link name="roller_11_rim_front_link">
    <inertial>
      <inertia ixx="1e-6" ixy="0.0" ixz="0.0" iyy="1e-6" iyz="0.0" izz="1e-7"/>
      <mass value="0.010"/>
    </inertial>
    <visual>
      <geometry>
        <cylinder length="0.03" radius="0.01"/>
      </geometry>
    </visual>
    <collision>
      <geometry>
        <cylinder length="0.03" radius="0.01"/>
      </geometry>
    </collision>
  </link>
  <joint name="roller_11_rim_front_joint" type="continuous">
    <parent link="rim_front_link"/>
    <child link="roller_11_rim_front_link"/>
    <axis xyz="0 0 1"/>
    <origin rpy="1.57 0 -2.6165" xyz="-0.05196 -0.03 -0.01"/>
    <limit effort="1000" velocity="31.4"/>
  </joint>
  <link name="roller_10_rim_front_link">
    <inertial>
      <inertia ixx="1e-6" ixy="0.0" ixz="0.0" iyy="1e-6" iyz="0.0" izz="1e-7"/>
      <mass value="0.010"/>
    </inertial>
    <visual>
      <geometry>
        <cylinder length="0.03" radius="0.01"/>
      </geometry>
    </visual>
    <collision>
      <geometry>
        <cylinder length="0.03" radius="0.01"/>
      </geometry>
    </collision>
  </link>
  <joint name="roller_10_rim_front_joint" type="continuous">
    <parent link="rim_front_link"/>
    <child link="roller_10_rim_front_link"/>
    <axis xyz="0 0 1"/>
    <origin rpy="1.57 0 -2.0932" xyz="-0.03 -0.05196 0.01"/>
    <limit effort="1000" velocity="31.4"/>
  </joint>
  <link name="roller_9_rim_front_link">
    <inertial>
      <inertia ixx="1e-6" ixy="0.0" ixz="0.0" iyy="1e-6" iyz="0.0" izz="1e-7"/>
      <mass value="0.010"/>
    </inertial>
    <visual>
      <geometry>
        <cylinder length="0.03" radius="0.01"/>
      </geometry>
    </visual>
    <collision>
      <geometry>
        <cylinder length="0.03" radius="0.01"/>
      </geometry>
    </collision>
  </link>
  <joint name="roller_9_rim_front_joint" type="continuous">
    <parent link="rim_front_link"/>
    <child link="roller_9_rim_front_link"/>
    <axis xyz="0 0 1"/>
    <origin rpy="1.57 0 -1.5699" xyz="0.0 -0.06 -0.01"/>
    <limit effort="1000" velocity="31.4"/>
  </joint>
  <link name="roller_8_rim_front_link">
    <inertial>
      <inertia ixx="1e-6" ixy="0.0" ixz="0.0" iyy="1e-6" iyz="0.0" izz="1e-7"/>
      <mass value="0.010"/>
    </inertial>
    <visual>
      <geometry>
        <cylinder length="0.03" radius="0.01"/>
      </geometry>
    </visual>
    <collision>
      <geometry>
        <cylinder length="0.03" radius="0.01"/>
      </geometry>
    </collision>
  </link>
  <joint name="roller_8_rim_front_joint" type="continuous">
    <parent link="rim_front_link"/>
    <child link="roller_8_rim_front_link"/>
    <axis xyz="0 0 1"/>
    <origin rpy="1.57 0 -1.0466" xyz="0.03 -0.05196 0.01"/>
    <limit effort="1000" velocity="31.4"/>
  </joint>
  <link name="roller_7_rim_front_link">
    <inertial>
      <inertia ixx="1e-6" ixy="0.0" ixz="0.0" iyy="1e-6" iyz="0.0" izz="1e-7"/>
      <mass value="0.010"/>
    </inertial>
    <visual>
      <geometry>
        <cylinder length="0.03" radius="0.01"/>
      </geometry>
    </visual>
    <collision>
      <geometry>
        <cylinder length="0.03" radius="0.01"/>
      </geometry>
    </collision>
  </link>
  <joint name="roller_7_rim_front_joint" type="continuous">
    <parent link="rim_front_link"/>
    <child link="roller_7_rim_front_link"/>
    <axis xyz="0 0 1"/>
    <origin rpy="1.57 0 -0.5233" xyz="0.05196 -0.03 -0.01"/>
    <limit effort="1000" velocity="31.4"/>
  </joint>
  <!-- <transmission name="front_wheel_tran">
    <type>transmission_interface/SimpleTransmission</type>
    <joint name="base_link_rim_front_joint">
      <hardwareInterface>hardware_interface/EffortJointInterface</hardwareInterface>
    </joint>
    <actuator name="front_wheel_motor">
      <hardwareInterface>hardware_interface/EffortJointInterface</hardwareInterface>
      <mechanicalReduction>1</mechanicalReduction>
    </actuator>
  </transmission> -->
  <gazebo reference="rim_front_link">
    <material value="Gazebo/Green"/>
  </gazebo>
  <gazebo>
    <plugin
      filename="gz-sim-joint-controller-system"
      name="gz::sim::systems::JointController">
      <joint_name>base_link_rim_front_joint</joint_name>
      <initial_velocity>0.0</initial_velocity>
      <topic>front_vel</topic>
    </plugin>
  </gazebo>
  <gazebo>
    <plugin
      filename="gz-sim-joint-controller-system"
      name="gz::sim::systems::JointController">
      <joint_name>base_link_rim_right_joint</joint_name>
      <initial_velocity>1.0</initial_velocity>
      <topic>right_vel</topic>
    </plugin>
  </gazebo>
  <gazebo>
    <plugin
      filename="gz-sim-joint-controller-system"
      name="gz::sim::systems::JointController">
      <joint_name>base_link_rim_left_joint</joint_name>
      <initial_velocity>-1.0</initial_velocity>
      <topic>left_vel</topic>
    </plugin>
  </gazebo>
  <!-- <gazebo>
    <plugin
      filename="gz-sim-joint-state-publisher-system"
      name="gz::sim::systems::JointStatePublisher">
      <joint_name>base_link_rim_front_joint</joint_name>
    </plugin>
  </gazebo> -->

</robot>
